{
  "success": false,
  "error": "Traceback (most recent call last):\n  File \"C:\\Users\\Yeort\\anaconda3\\lib\\site-packages\\crytic_compile\\platform\\solc.py\", line 559, in _run_solc\n    ret: Dict = json.loads(stdout)\n  File \"C:\\Users\\Yeort\\anaconda3\\lib\\json\\__init__.py\", line 346, in loads\n    return _default_decoder.decode(s)\n  File \"C:\\Users\\Yeort\\anaconda3\\lib\\json\\decoder.py\", line 337, in decode\n    obj, end = self.raw_decode(s, idx=_w(s, 0).end())\n  File \"C:\\Users\\Yeort\\anaconda3\\lib\\json\\decoder.py\", line 355, in raw_decode\n    raise JSONDecodeError(\"Expecting value\", s, err.value) from None\njson.decoder.JSONDecodeError: Expecting value: line 2 column 1 (char 2)\n\nDuring handling of the above exception, another exception occurred:\n\nTraceback (most recent call last):\n  File \"C:\\Users\\Yeort\\anaconda3\\lib\\site-packages\\slither\\__main__.py\", line 834, in main_impl\n    ) = process_all(filename, args, detector_classes, printer_classes)\n  File \"C:\\Users\\Yeort\\anaconda3\\lib\\site-packages\\slither\\__main__.py\", line 87, in process_all\n    compilations = compile_all(target, **vars(args))\n  File \"C:\\Users\\Yeort\\anaconda3\\lib\\site-packages\\crytic_compile\\crytic_compile.py\", line 641, in compile_all\n    compilations.append(CryticCompile(filename, **kwargs))\n  File \"C:\\Users\\Yeort\\anaconda3\\lib\\site-packages\\crytic_compile\\crytic_compile.py\", line 110, in __init__\n    self._compile(**kwargs)\n  File \"C:\\Users\\Yeort\\anaconda3\\lib\\site-packages\\crytic_compile\\crytic_compile.py\", line 530, in _compile\n    self._platform.compile(self, **kwargs)\n  File \"C:\\Users\\Yeort\\anaconda3\\lib\\site-packages\\crytic_compile\\platform\\solc.py\", line 154, in compile\n    targets_json = _get_targets_json(compilation_unit, self._target, **kwargs)\n  File \"C:\\Users\\Yeort\\anaconda3\\lib\\site-packages\\crytic_compile\\platform\\solc.py\", line 283, in _get_targets_json\n    return _run_solc(\n  File \"C:\\Users\\Yeort\\anaconda3\\lib\\site-packages\\crytic_compile\\platform\\solc.py\", line 563, in _run_solc\n    raise InvalidCompilation(f\"Invalid solc compilation {stderr}\")\ncrytic_compile.platform.exceptions.InvalidCompilation: Invalid solc compilation usage: solc-select install [-h] [INSTALL_VERSIONS ...]\r\nsolc-select install: error: argument INSTALL_VERSIONS: Invalid version - only solc versions above '0.4.5' are available\r\nusage: solc-select install [-h] [INSTALL_VERSIONS ...]\r\nsolc-select install: error: argument INSTALL_VERSIONS: Invalid version - only solc versions above '0.4.5' are available\r\nTraceback (most recent call last):\r\n  File \"C:\\Users\\Yeort\\anaconda3\\lib\\urllib\\request.py\", line 1346, in do_open\r\n    h.request(req.get_method(), req.selector, req.data, headers,\r\n  File \"C:\\Users\\Yeort\\anaconda3\\lib\\http\\client.py\", line 1285, in request\r\n    self._send_request(method, url, body, headers, encode_chunked)\r\n  File \"C:\\Users\\Yeort\\anaconda3\\lib\\http\\client.py\", line 1331, in _send_request\r\n    self.endheaders(body, encode_chunked=encode_chunked)\r\n  File \"C:\\Users\\Yeort\\anaconda3\\lib\\http\\client.py\", line 1280, in endheaders\r\n    self._send_output(message_body, encode_chunked=encode_chunked)\r\n  File \"C:\\Users\\Yeort\\anaconda3\\lib\\http\\client.py\", line 1040, in _send_output\r\n    self.send(msg)\r\n  File \"C:\\Users\\Yeort\\anaconda3\\lib\\http\\client.py\", line 980, in send\r\n    self.connect()\r\n  File \"C:\\Users\\Yeort\\anaconda3\\lib\\http\\client.py\", line 1454, in connect\r\n    self.sock = self._context.wrap_socket(self.sock,\r\n  File \"C:\\Users\\Yeort\\anaconda3\\lib\\ssl.py\", line 501, in wrap_socket\r\n    return self.sslsocket_class._create(\r\n  File \"C:\\Users\\Yeort\\anaconda3\\lib\\ssl.py\", line 1041, in _create\r\n    self.do_handshake()\r\n  File \"C:\\Users\\Yeort\\anaconda3\\lib\\ssl.py\", line 1310, in do_handshake\r\n    self._sslobj.do_handshake()\r\nFileNotFoundError: [Errno 2] No such file or directory\r\n\r\nDuring handling of the above exception, another exception occurred:\r\n\r\nTraceback (most recent call last):\r\n  File \"C:\\Users\\Yeort\\anaconda3\\lib\\runpy.py\", line 197, in _run_module_as_main\r\n    return _run_code(code, main_globals, None,\r\n  File \"C:\\Users\\Yeort\\anaconda3\\lib\\runpy.py\", line 87, in _run_code\r\n    exec(code, run_globals)\r\n  File \"C:\\Users\\Yeort\\anaconda3\\Scripts\\solc-select.exe\\__main__.py\", line 7, in <module>\r\n  File \"C:\\Users\\Yeort\\anaconda3\\lib\\site-packages\\solc_select\\__main__.py\", line 49, in solc_select\r\n    args = vars(parser.parse_args())\r\n  File \"C:\\Users\\Yeort\\anaconda3\\lib\\argparse.py\", line 1825, in parse_args\r\n    args, argv = self.parse_known_args(args, namespace)\r\n  File \"C:\\Users\\Yeort\\anaconda3\\lib\\argparse.py\", line 1858, in parse_known_args\r\n    namespace, args = self._parse_known_args(args, namespace)\r\n  File \"C:\\Users\\Yeort\\anaconda3\\lib\\argparse.py\", line 2070, in _parse_known_args\r\n    stop_index = consume_positionals(start_index)\r\n  File \"C:\\Users\\Yeort\\anaconda3\\lib\\argparse.py\", line 2026, in consume_positionals\r\n    take_action(action, args)\r\n  File \"C:\\Users\\Yeort\\anaconda3\\lib\\argparse.py\", line 1935, in take_action\r\n    action(self, namespace, argument_values, option_string)\r\n  File \"C:\\Users\\Yeort\\anaconda3\\lib\\argparse.py\", line 1214, in __call__\r\n    subnamespace, arg_strings = parser.parse_known_args(arg_strings, None)\r\n  File \"C:\\Users\\Yeort\\anaconda3\\lib\\argparse.py\", line 1858, in parse_known_args\r\n    namespace, args = self._parse_known_args(args, namespace)\r\n  File \"C:\\Users\\Yeort\\anaconda3\\lib\\argparse.py\", line 2070, in _parse_known_args\r\n    stop_index = consume_positionals(start_index)\r\n  File \"C:\\Users\\Yeort\\anaconda3\\lib\\argparse.py\", line 2026, in consume_positionals\r\n    take_action(action, args)\r\n  File \"C:\\Users\\Yeort\\anaconda3\\lib\\argparse.py\", line 1919, in take_action\r\n    argument_values = self._get_values(action, argument_strings)\r\n  File \"C:\\Users\\Yeort\\anaconda3\\lib\\argparse.py\", line 2468, in _get_values\r\n    value = [self._get_value(action, v) for v in arg_strings]\r\n  File \"C:\\Users\\Yeort\\anaconda3\\lib\\argparse.py\", line 2468, in <listcomp>\r\n    value = [self._get_value(action, v) for v in arg_strings]\r\n  File \"C:\\Users\\Yeort\\anaconda3\\lib\\argparse.py\", line 2483, in _get_value\r\n    result = type_func(arg_string)\r\n  File \"C:\\Users\\Yeort\\anaconda3\\lib\\site-packages\\solc_select\\solc_select.py\", line 213, in valid_install_arg\r\n    return valid_version(arg)\r\n  File \"C:\\Users\\Yeort\\anaconda3\\lib\\site-packages\\solc_select\\solc_select.py\", line 199, in valid_version\r\n    list_json = urllib.request.urlopen(list_url).read()\r\n  File \"C:\\Users\\Yeort\\anaconda3\\lib\\urllib\\request.py\", line 214, in urlopen\r\n    return opener.open(url, data, timeout)\r\n  File \"C:\\Users\\Yeort\\anaconda3\\lib\\urllib\\request.py\", line 517, in open\r\n    response = self._open(req, data)\r\n  File \"C:\\Users\\Yeort\\anaconda3\\lib\\urllib\\request.py\", line 534, in _open\r\n    result = self._call_chain(self.handle_open, protocol, protocol +\r\n  File \"C:\\Users\\Yeort\\anaconda3\\lib\\urllib\\request.py\", line 494, in _call_chain\r\n    result = func(*args)\r\n  File \"C:\\Users\\Yeort\\anaconda3\\lib\\urllib\\request.py\", line 1389, in https_open\r\n    return self.do_open(http.client.HTTPSConnection, req,\r\n  File \"C:\\Users\\Yeort\\anaconda3\\lib\\urllib\\request.py\", line 1349, in do_open\r\n    raise URLError(err)\r\nurllib.error.URLError: <urlopen error [Errno 2] No such file or directory>\r\n\n",
  "results": {}
}